Workbook

Sheet Istruzioni
A1: REGISTRO DI EDUCAZIONE MOTORIA · MODELLO-5 · Manzoni · classe 5ª · a.s. 2026/27
A3: 1 · Calendario | B3: Una riga per giornata di prova. Scrivi il LUNEDÌ della settimana nella colonna del tuo plesso: la data della classe si calcola dal giorno di lezione. Scegli fino a 4 sotto-obiettivi. «Controllo» diventa rosso se un sotto-obiettivo si ripete nella giornata o a meno di 9 giorni.
A4: 2 · Alunni | B4: Nomi in ordine alfabetico accanto ai numeri. Il numero è il codice dell'alunno tutto l'anno. Nuovi alunni nel primo numero libero in fondo; chi lascia: Stato = Ritirato. OP = obiettivi personalizzati (Impostazioni).
A5: 3 · Registro | B5: Un blocco per giornata (indice cliccabile in alto). Per ogni sotto-obiettivo scrivi il livello (10–5) negli indicatori che usi: VOTO = media degli indicatori compilati arrotondata all'intero (da ,50 per eccesso); GIUDIZIO = da riportare su Argo. Tocca il nome di un indicatore per aprire la sua rubrica. Stato: AS assente · NV non valutabile · ES esonerato; al recupero scrivi i livelli e la data.
A6: 4 · Riepilogo | B6: Unico per i due quadrimestri. Per ogni Q: giudizio calcolato per obiettivo di scheda (media ponderata di tutti i voti collegati: peso 1 / 1,5 dopo la metà del Q; 80% prove + 20% rubrica di processo se compilata). «Giudizio definitivo» è tuo e prevale. Le colonne verdi «Da riportare» vanno nel documento di valutazione. Il pulsante «+» sopra le colonne mostra i dettagli (medie per sotto-obiettivo).
A7: 5 · Verifica voti | B7: Come su Argo: una riga per alunno, una colonna per giornata con i voti di quel giorno raggruppati (es. 1.1: 8 · 1.2: 7). Serve a confrontare il file con agenda e registro elettronico.
A8: 6 · Giochi | B8: Tempi e punteggi delle prove d'istituto calcolati come da schede tecniche (Super Gym: tempo + penalità; Triathlon; Spikeball). Due rilevazioni. Le statistiche di classe alimenteranno il database del gestionale.
A9: 7 · Rubriche | B9: Per ogni sotto-obiettivo 4 indicatori × 6 livelli (descrittori costruiti sui giudizi dell'Allegato A, OM 3/2025). Passa sul nome dell'indicatore per vedere i descrittori.
A10: 8 · Impostazioni | B10: Classe, giorno di lezione, pesi, soglie, obiettivi della scheda, sotto-obiettivi (con «concorre a» per Q1/Q2) e obiettivi personalizzati.
A11: Celle | B11: Gialle = da compilare. Tutto il resto si calcola.

Sheet Calendario
A1: CALENDARIO DELLE GIORNATE DI PROVA · stessa sequenza per Manzoni e Boncompagni
A2: ="Classe "&Impostazioni!$B$3&" · plesso "&Impostazioni!$B$5&" · lezione il "&Impostazioni!$B$6&" · la lezione successiva a ogni giornata è di recupero" -> Classe MODELLO-5 · plesso Manzoni · lezione il Lunedì · la lezione successiva a ogni giornata è di recupero
A3: Regola: lo stesso sotto-obiettivo non si valuta due volte nella stessa giornata né in giornate a meno di 9 giorni (gli assenti devono poter recuperare).
C5: Settimana (lunedì)
A6: Q | B6: Giornata | C6: Manzoni | D6: Boncompagni | E6: Data classe | F6: Metà | G6: Descrizione della prova | H6: Sott-ob. 1 | I6: Sott-ob. 2 | J6: Sott-ob. 3 | K6: Sott-ob. 4 | L6: Controllo regole
A7: Q1 | B7: Q1-G01 | C7: 46293 | D7: 46293 | E7: =IF(IF(Impostazioni!$B$5="Boncompagni",D7,C7)="","",IF(Impostazioni!$B$5="Boncompagni",D7,C7)+Impostazioni!$B$7) -> 46293 | F7: =IF(E7="",1,IF(E7>=Impostazioni!$B$8,2,1)) -> 1 | G7: Test d'ingresso – schemi motori di base | H7: 1.1 | L7: =IF(COUNTA($H7:$K7)=0,"",IF(SUMPRODUCT(($H7:$K7<>"")*(COUNTIF($H7:$K7,$H7:$K7)>1))>0,"⚠ stesso sotto-obiettivo 2 volte nella giornata","OK")) -> OK
A8: Q1 | B8: Q1-G02 | C8: 46321 | E8: =IF(IF(Impostazioni!$B$5="Boncompagni",D8,C8)="","",IF(Impostazioni!$B$5="Boncompagni",D8,C8)+Impostazioni!$B$7) -> 46321 | F8: =IF(E8="",1,IF(E8>=Impostazioni!$B$8,2,1)) -> 1 | G8: Progetto basket – osservazione (lezioni con l'esperto) | H8: 3.1 | I8: 3.3 | L8: =IF(COUNTA($H8:$K8)=0,"",IF(SUMPRODUCT(($H8:$K8<>"")*(COUNTIF($H8:$K8,$H8:$K8)>1))>0,"⚠ stesso sotto-obiettivo 2 volte nella giornata",IF(AND(IFERROR(AND(ISNUMBER(E7),ISNUMBER(E8),E8-E7<=8),FALSE()),SUMPRODUCT(($H8:$K8<>"")*(COUNTIF($H7:$K7,$H8:$K8)>0))>0),"⚠ ripetuto a meno di 9 giorni: niente recupero","OK"))) -> OK
A9: Q1 | B9: Q1-G03 | C9: 46328 | E9: =IF(IF(Impostazioni!$B$5="Boncompagni",D9,C9)="","",IF(Impostazioni!$B$5="Boncompagni",D9,C9)+Impostazioni!$B$7) -> 46328 | F9: =IF(E9="",1,IF(E9>=Impostazioni!$B$8,2,1)) -> 1 | G9: P02 · Circuito Super Gym d'istituto | H9: 1.1 | I9: TEC.1 | L9: =IF(COUNTA($H9:$K9)=0,"",IF(SUMPRODUCT(($H9:$K9<>"")*(COUNTIF($H9:$K9,$H9:$K9)>1))>0,"⚠ stesso sotto-obiettivo 2 volte nella giornata",IF(AND(IFERROR(AND(ISNUMBER(E8),ISNUMBER(E9),E9-E8<=8),FALSE()),SUMPRODUCT(($H9:$K9<>"")*(COUNTIF($H8:$K8,$H9:$K9)>0))>0),"⚠ ripetuto a meno di 9 giorni: niente recupero","OK"))) -> OK
A10: Q1 | B10: Q1-G04 | E10: =IF(IF(Impostazioni!$B$5="Boncompagni",D10,C10)="","",IF(Impostazioni!$B$5="Boncompagni",D10,C10)+Impostazioni!$B$7) | F10: =IF(E10="",1,IF(E10>=Impostazioni!$B$8,2,1)) -> 1 | L10: =IF(COUNTA($H10:$K10)=0,"",IF(SUMPRODUCT(($H10:$K10<>"")*(COUNTIF($H10:$K10,$H10:$K10)>1))>0,"⚠ stesso sotto-obiettivo 2 volte nella giornata",IF(AND(IFERROR(AND(ISNUMBER(E9),ISNUMBER(E10),E10-E9<=8),FALSE()),SUMPRODUCT(($H10:$K10<>"")*(COUNTIF($H9:$K9,$H10:$K10)>0))>0),"⚠ ripetuto a meno di 9 giorni: niente recupero","OK")))
A11: Q1 | B11: Q1-G05 | E11: =IF(IF(Impostazioni!$B$5="Boncompagni",D11,C11)="","",IF(Impostazioni!$B$5="Boncompagni",D11,C11)+Impostazioni!$B$7) | F11: =IF(E11="",1,IF(E11>=Impostazioni!$B$8,2,1)) -> 1 | L11: =IF(COUNTA($H11:$K11)=0,"",IF(SUMPRODUCT(($H11:$K11<>"")*(COUNTIF($H11:$K11,$H11:$K11)>1))>0,"⚠ stesso sotto-obiettivo 2 volte nella giornata",IF(AND(IFERROR(AND(ISNUMBER(E10),ISNUMBER(E11),E11-E10<=8),FALSE()),SUMPRODUCT(($H11:$K11<>"")*(COUNTIF($H10:$K10,$H11:$K11)>0))>0),"⚠ ripetuto a meno di 9 giorni: niente recupero","OK")))
A12: Q1 | B12: Q1-G06 | E12: =IF(IF(Impostazioni!$B$5="Boncompagni",D12,C12)="","",IF(Impostazioni!$B$5="Boncompagni",D12,C12)+Impostazioni!$B$7) | F12: =IF(E12="",1,IF(E12>=Impostazioni!$B$8,2,1)) -> 1 | L12: =IF(COUNTA($H12:$K12)=0,"",IF(SUMPRODUCT(($H12:$K12<>"")*(COUNTIF($H12:$K12,$H12:$K12)>1))>0,"⚠ stesso sotto-obiettivo 2 volte nella giornata",IF(AND(IFERROR(AND(ISNUMBER(E11),ISNUMBER(E12),E12-E11<=8),FALSE()),SUMPRODUCT(($H12:$K12<>"")*(COUNTIF($H11:$K11,$H12:$K12)>0))>0),"⚠ ripetuto a meno di 9 giorni: niente recupero","OK")))
A13: Q1 | B13: Q1-G07 | E13: =IF(IF(Impostazioni!$B$5="Boncompagni",D13,C13)="","",IF(Impostazioni!$B$5="Boncompagni",D13,C13)+Impostazioni!$B$7) | F13: =IF(E13="",1,IF(E13>=Impostazioni!$B$8,2,1)) -> 1 | L13: =IF(COUNTA($H13:$K13)=0,"",IF(SUMPRODUCT(($H13:$K13<>"")*(COUNTIF($H13:$K13,$H13:$K13)>1))>0,"⚠ stesso sotto-obiettivo 2 volte nella giornata",IF(AND(IFERROR(AND(ISNUMBER(E12),ISNUMBER(E13),E13-E12<=8),FALSE()),SUMPRODUCT(($H13:$K13<>"")*(COUNTIF($H12:$K12,$H13:$K13)>0))>0),"⚠ ripetuto a meno di 9 giorni: niente recupero","OK")))
A14: Q1 | B14: Q1-G08 | E14: =IF(IF(Impostazioni!$B$5="Boncompagni",D14,C14)="","",IF(Impostazioni!$B$5="Boncompagni",D14,C14)+Impostazioni!$B$7) | F14: =IF(E14="",1,IF(E14>=Impostazioni!$B$8,2,1)) -> 1 | L14: =IF(COUNTA($H14:$K14)=0,"",IF(SUMPRODUCT(($H14:$K14<>"")*(COUNTIF($H14:$K14,$H14:$K14)>1))>0,"⚠ stesso sotto-obiettivo 2 volte nella giornata",IF(AND(IFERROR(AND(ISNUMBER(E13),ISNUMBER(E14),E14-E13<=8),FALSE()),SUMPRODUCT(($H14:$K14<>"")*(COUNTIF($H13:$K13,$H14:$K14)>0))>0),"⚠ ripetuto a meno di 9 giorni: niente recupero","OK")))
A15: Q1 | B15: Q1-G09 | E15: =IF(IF(Impostazioni!$B$5="Boncompagni",D15,C15)="","",IF(Impostazioni!$B$5="Boncompagni",D15,C15)+Impostazioni!$B$7) | F15: =IF(E15="",1,IF(E15>=Impostazioni!$B$8,2,1)) -> 1 | L15: =IF(COUNTA($H15:$K15)=0,"",IF(SUMPRODUCT(($H15:$K15<>"")*(COUNTIF($H15:$K15,$H15:$K15)>1))>0,"⚠ stesso sotto-obiettivo 2 volte nella giornata",IF(AND(IFERROR(AND(ISNUMBER(E14),ISNUMBER(E15),E15-E14<=8),FALSE()),SUMPRODUCT(($H15:$K15<>"")*(COUNTIF($H14:$K14,$H15:$K15)>0))>0),"⚠ ripetuto a meno di 9 giorni: niente recupero","OK")))
A16: Q1 | B16: Q1-G10 | E16: =IF(IF(Impostazioni!$B$5="Boncompagni",D16,C16)="","",IF(Impostazioni!$B$5="Boncompagni",D16,C16)+Impostazioni!$B$7) | F16: =IF(E16="",1,IF(E16>=Impostazioni!$B$8,2,1)) -> 1 | L16: =IF(COUNTA($H16:$K16)=0,"",IF(SUMPRODUCT(($H16:$K16<>"")*(COUNTIF($H16:$K16,$H16:$K16)>1))>0,"⚠ stesso sotto-obiettivo 2 volte nella giornata",IF(AND(IFERROR(AND(ISNUMBER(E15),ISNUMBER(E16),E16-E15<=8),FALSE()),SUMPRODUCT(($H16:$K16<>"")*(COUNTIF($H15:$K15,$H16:$K16)>0))>0),"⚠ ripetuto a meno di 9 giorni: niente recupero","OK")))
A17: Q2 | B17: Q2-G01 | E17: =IF(IF(Impostazioni!$B$5="Boncompagni",D17,C17)="","",IF(Impostazioni!$B$5="Boncompagni",D17,C17)+Impostazioni!$B$7) | F17: =IF(E17="",1,IF(E17>=Impostazioni!$B$9,2,1)) -> 1 | L17: =IF(COUNTA($H17:$K17)=0,"",IF(SUMPRODUCT(($H17:$K17<>"")*(COUNTIF($H17:$K17,$H17:$K17)>1))>0,"⚠ stesso sotto-obiettivo 2 volte nella giornata","OK"))
A18: Q2 | B18: Q2-G02 | E18: =IF(IF(Impostazioni!$B$5="Boncompagni",D18,C18)="","",IF(Impostazioni!$B$5="Boncompagni",D18,C18)+Impostazioni!$B$7) | F18: =IF(E18="",1,IF(E18>=Impostazioni!$B$9,2,1)) -> 1 | L18: =IF(COUNTA($H18:$K18)=0,"",IF(SUMPRODUCT(($H18:$K18<>"")*(COUNTIF($H18:$K18,$H18:$K18)>1))>0,"⚠ stesso sotto-obiettivo 2 volte nella giornata",IF(AND(IFERROR(AND(ISNUMBER(E17),ISNUMBER(E18),E18-E17<=8),FALSE()),SUMPRODUCT(($H18:$K18<>"")*(COUNTIF($H17:$K17,$H18:$K18)>0))>0),"⚠ ripetuto a meno di 9 giorni: niente recupero","OK")))
A19: Q2 | B19: Q2-G03 | E19: =IF(IF(Impostazioni!$B$5="Boncompagni",D19,C19)="","",IF(Impostazioni!$B$5="Boncompagni",D19,C19)+Impostazioni!$B$7) | F19: =IF(E19="",1,IF(E19>=Impostazioni!$B$9,2,1)) -> 1 | L19: =IF(COUNTA($H19:$K19)=0,"",IF(SUMPRODUCT(($H19:$K19<>"")*(COUNTIF($H19:$K19,$H19:$K19)>1))>0,"⚠ stesso sotto-obiettivo 2 volte nella giornata",IF(AND(IFERROR(AND(ISNUMBER(E18),ISNUMBER(E19),E19-E18<=8),FALSE()),SUMPRODUCT(($H19:$K19<>"")*(COUNTIF($H18:$K18,$H19:$K19)>0))>0),"⚠ ripetuto a meno di 9 giorni: niente recupero","OK")))
A20: Q2 | B20: Q2-G04 | E20: =IF(IF(Impostazioni!$B$5="Boncompagni",D20,C20)="","",IF(Impostazioni!$B$5="Boncompagni",D20,C20)+Impostazioni!$B$7) | F20: =IF(E20="",1,IF(E20>=Impostazioni!$B$9,2,1)) -> 1 | L20: =IF(COUNTA($H20:$K20)=0,"",IF(SUMPRODUCT(($H20:$K20<>"")*(COUNTIF($H20:$K20,$H20:$K20)>1))>0,"⚠ stesso sotto-obiettivo 2 volte nella giornata",IF(AND(IFERROR(AND(ISNUMBER(E19),ISNUMBER(E20),E20-E19<=8),FALSE()),SUMPRODUCT(($H20:$K20<>"")*(COUNTIF($H19:$K19,$H20:$K20)>0))>0),"⚠ ripetuto a meno di 9 giorni: niente recupero","OK")))
A21: Q2 | B21: Q2-G05 | E21: =IF(IF(Impostazioni!$B$5="Boncompagni",D21,C21)="","",IF(Impostazioni!$B$5="Boncompagni",D21,C21)+Impostazioni!$B$7) | F21: =IF(E21="",1,IF(E21>=Impostazioni!$B$9,2,1)) -> 1 | L21: =IF(COUNTA($H21:$K21)=0,"",IF(SUMPRODUCT(($H21:$K21<>"")*(COUNTIF($H21:$K21,$H21:$K21)>1))>0,"⚠ stesso sotto-obiettivo 2 volte nella giornata",IF(AND(IFERROR(AND(ISNUMBER(E20),ISNUMBER(E21),E21-E20<=8),FALSE()),SUMPRODUCT(($H21:$K21<>"")*(COUNTIF($H20:$K20,$H21:$K21)>0))>0),"⚠ ripetuto a meno di 9 giorni: niente recupero","OK")))
A22: Q2 | B22: Q2-G06 | E22: =IF(IF(Impostazioni!$B$5="Boncompagni",D22,C22)="","",IF(Impostazioni!$B$5="Boncompagni",D22,C22)+Impostazioni!$B$7) | F22: =IF(E22="",1,IF(E22>=Impostazioni!$B$9,2,1)) -> 1 | L22: =IF(COUNTA($H22:$K22)=0,"",IF(SUMPRODUCT(($H22:$K22<>"")*(COUNTIF($H22:$K22,$H22:$K22)>1))>0,"⚠ stesso sotto-obiettivo 2 volte nella giornata",IF(AND(IFERROR(AND(ISNUMBER(E21),ISNUMBER(E22),E22-E21<=8),FALSE()),SUMPRODUCT(($H22:$K22<>"")*(COUNTIF($H21:$K21,$H22:$K22)>0))>0),"⚠ ripetuto a meno di 9 giorni: niente recupero","OK")))
A23: Q2 | B23: Q2-G07 | E23: =IF(IF(Impostazioni!$B$5="Boncompagni",D23,C23)="","",IF(Impostazioni!$B$5="Boncompagni",D23,C23)+Impostazioni!$B$7) | F23: =IF(E23="",1,IF(E23>=Impostazioni!$B$9,2,1)) -> 1 | L23: =IF(COUNTA($H23:$K23)=0,"",IF(SUMPRODUCT(($H23:$K23<>"")*(COUNTIF($H23:$K23,$H23:$K23)>1))>0,"⚠ stesso sotto-obiettivo 2 volte nella giornata",IF(AND(IFERROR(AND(ISNUMBER(E22),ISNUMBER(E23),E23-E22<=8),FALSE()),SUMPRODUCT(($H23:$K23<>"")*(COUNTIF($H22:$K22,$H23:$K23)>0))>0),"⚠ ripetuto a meno di 9 giorni: niente recupero","OK")))
A24: Q2 | B24: Q2-G08 | E24: =IF(IF(Impostazioni!$B$5="Boncompagni",D24,C24)="","",IF(Impostazioni!$B$5="Boncompagni",D24,C24)+Impostazioni!$B$7) | F24: =IF(E24="",1,IF(E24>=Impostazioni!$B$9,2,1)) -> 1 | L24: =IF(COUNTA($H24:$K24)=0,"",IF(SUMPRODUCT(($H24:$K24<>"")*(COUNTIF($H24:$K24,$H24:$K24)>1))>0,"⚠ stesso sotto-obiettivo 2 volte nella giornata",IF(AND(IFERROR(AND(ISNUMBER(E23),ISNUMBER(E24),E24-E23<=8),FALSE()),SUMPRODUCT(($H24:$K24<>"")*(COUNTIF($H23:$K23,$H24:$K24)>0))>0),"⚠ ripetuto a meno di 9 giorni: niente recupero","OK")))
A25: Q2 | B25: Q2-G09 | E25: =IF(IF(Impostazioni!$B$5="Boncompagni",D25,C25)="","",IF(Impostazioni!$B$5="Boncompagni",D25,C25)+Impostazioni!$B$7) | F25: =IF(E25="",1,IF(E25>=Impostazioni!$B$9,2,1)) -> 1 | L25: =IF(COUNTA($H25:$K25)=0,"",IF(SUMPRODUCT(($H25:$K25<>"")*(COUNTIF($H25:$K25,$H25:$K25)>1))>0,"⚠ stesso sotto-obiettivo 2 volte nella giornata",IF(AND(IFERROR(AND(ISNUMBER(E24),ISNUMBER(E25),E25-E24<=8),FALSE()),SUMPRODUCT(($H25:$K25<>"")*(COUNTIF($H24:$K24,$H25:$K25)>0))>0),"⚠ ripetuto a meno di 9 giorni: niente recupero","OK")))
A26: Q2 | B26: Q2-G10 | E26: =IF(IF(Impostazioni!$B$5="Boncompagni",D26,C26)="","",IF(Impostazioni!$B$5="Boncompagni",D26,C26)+Impostazioni!$B$7) | F26: =IF(E26="",1,IF(E26>=Impostazioni!$B$9,2,1)) -> 1 | L26: =IF(COUNTA($H26:$K26)=0,"",IF(SUMPRODUCT(($H26:$K26<>"")*(COUNTIF($H26:$K26,$H26:$K26)>1))>0,"⚠ stesso sotto-obiettivo 2 volte nella giornata",IF(AND(IFERROR(AND(ISNUMBER(E25),ISNUMBER(E26),E26-E25<=8),FALSE()),SUMPRODUCT(($H26:$K26<>"")*(COUNTIF($H25:$K25,$H26:$K26)>0))>0),"⚠ ripetuto a meno di 9 giorni: niente recupero","OK")))

Sheet Alunni
A1: ALUNNI · MODELLO-5 · anagrafica di riferimento per tutti i fogli
A2: Ordine alfabetico · numero fisso tutto l'anno · nuovi alunni in fondo · Stato: Attivo / Ritirato / ES · OP = obiettivi personalizzati
A4: N° | B4: Codice | C4: Cognome e nome | D4: Stato | E4: OP | F4: Note didattiche (no dati sanitari)
A5: 1 | B5: =Impostazioni!$B$3&"-"&TEXT(A5,"00") -> MODELLO-5-01 | C5: Rossi Mario (esempio) | D5: Attivo
A6: 2 | B6: =Impostazioni!$B$3&"-"&TEXT(A6,"00") -> MODELLO-5-02 | C6: Bianchi Anna (esempio) | D6: Attivo | E6: OP
A7: 3 | B7: =Impostazioni!$B$3&"-"&TEXT(A7,"00") -> MODELLO-5-03 | C7: Verdi Luca (esempio) | D7: ES
A8: 4 | B8: =Impostazioni!$B$3&"-"&TEXT(A8,"00") -> MODELLO-5-04
A9: 5 | B9: =Impostazioni!$B$3&"-"&TEXT(A9,"00") -> MODELLO-5-05
A10: 6 | B10: =Impostazioni!$B$3&"-"&TEXT(A10,"00") -> MODELLO-5-06
A11: 7 | B11: =Impostazioni!$B$3&"-"&TEXT(A11,"00") -> MODELLO-5-07
A12: 8 | B12: =Impostazioni!$B$3&"-"&TEXT(A12,"00") -> MODELLO-5-08
A13: 9 | B13: =Impostazioni!$B$3&"-"&TEXT(A13,"00") -> MODELLO-5-09
A14: 10 | B14: =Impostazioni!$B$3&"-"&TEXT(A14,"00") -> MODELLO-5-10
A15: 11 | B15: =Impostazioni!$B$3&"-"&TEXT(A15,"00") -> MODELLO-5-11
A16: 12 | B16: =Impostazioni!$B$3&"-"&TEXT(A16,"00") -> MODELLO-5-12
A17: 13 | B17: =Impostazioni!$B$3&"-"&TEXT(A17,"00") -> MODELLO-5-13
A18: 14 | B18: =Impostazioni!$B$3&"-"&TEXT(A18,"00") -> MODELLO-5-14
A19: 15 | B19: =Impostazioni!$B$3&"-"&TEXT(A19,"00") -> MODELLO-5-15
... A34: 30 | B34: =Impostazioni!$B$3&"-"&TEXT(A34,"00") -> MODELLO-5-30

Sheet Registro
A1: REGISTRO DELLE PROVE · MODELLO-5 · tocca una giornata per raggiungerla
B2: 1° quadrimestre › | C2: =HYPERLINK("#Registro!A6","G01") -> G01 | E2: =HYPERLINK("#Registro!A42","G02") -> G02 | G2: =HYPERLINK("#Registro!A78","G03") -> G03 | I2: =HYPERLINK("#Registro!A114","G04") -> G04 | K2: =HYPERLINK("#Registro!A150","G05") -> G05 | M2: =HYPERLINK("#Registro!A186","G06") -> G06 | O2: =HYPERLINK("#Registro!A222","G07") -> G07 | Q2: =HYPERLINK("#Registro!A258","G08") -> G08 | S2: =HYPERLINK("#Registro!A294","G09") -> G09 | U2: =HYPERLINK("#Registro!A330","G10") -> G10
B3: 2° quadrimestre › | C3: =HYPERLINK("#Registro!A366","G01") -> G01 | E3: =HYPERLINK("#Registro!A402","G02") -> G02 | G3: =HYPERLINK("#Registro!A438","G03") -> G03 | I3: =HYPERLINK("#Registro!A474","G04") -> G04 | K3: =HYPERLINK("#Registro!A510","G05") -> G05 | M3: =HYPERLINK("#Registro!A546","G06") -> G06 | O3: =HYPERLINK("#Registro!A582","G07") -> G07 | Q3: =HYPERLINK("#Registro!A618","G08") -> G08 | S3: =HYPERLINK("#Registro!A654","G09") -> G09 | U3: =HYPERLINK("#Registro!A690","G10") -> G10
A4: Livelli: 10 Ottimo · 9 Distinto · 8 Buono · 7 Discreto · 6 Sufficiente · 5 Non sufficiente · Stato: AS assente · NV non valutabile · ES esonerato
A6: =Calendario!B7&" · "&IF(Calendario!G7="","(descrizione da Calendario)",Calendario!G7)&" · "&IF(Calendario!E7="","data da fissare",CHOOSE(WEEKDAY(Calendario!E7,2),"lunedì","martedì","mercoledì","giovedì","venerdì","sabato","domenica")&" "&TEXT(DAY(Calendario!E7),"00")&"/"&TEXT(MONTH(Calendario!E7),"00")&"/"&YEAR(Calendario!E7)) -> Q1-G01 · Test d'ingresso – schemi motori di base · lunedì 28/09/2026
A7: Sotto-obiettivo | E7: =IF(Calendario!$H$7="","— libero —",Calendario!$H$7&" "&IFERROR(VLOOKUP(Calendario!$H$7,Impostazioni!$A$25:$J$36,3,FALSE()),"")) -> 1.1 Traiettorie, ritmi, organizzazione | K7: =IF(Calendario!$I$7="","— libero —",Calendario!$I$7&" "&IFERROR(VLOOKUP(Calendario!$I$7,Impostazioni!$A$25:$J$36,3,FALSE()),"")) -> — libero — | Q7: =IF(Calendario!$J$7="","— libero —",Calendario!$J$7&" "&IFERROR(VLOOKUP(Calendario!$J$7,Impostazioni!$A$25:$J$36,3,FALSE()),"")) -> — libero — | W7: =IF(Calendario!$K$7="","— libero —",Calendario!$K$7&" "&IFERROR(VLOOKUP(Calendario!$K$7,Impostazioni!$A$25:$J$36,3,FALSE()),"")) -> — libero —
A8: Concorre a | E8: =IF(Calendario!$H$7="","","Ob. "&IFERROR(VLOOKUP(Calendario!$H$7,Impostazioni!$A$25:$J$36,5,FALSE()),"?")&" · peso "&IF(Calendario!$F$7=2,Impostazioni!$B$11,Impostazioni!$B$10)) -> Ob. A · peso 1 | K8: =IF(Calendario!$I$7="","","Ob. "&IFERROR(VLOOKUP(Calendario!$I$7,Impostazioni!$A$25:$J$36,5,FALSE()),"?")&" · peso "&IF(Calendario!$F$7=2,Impostazioni!$B$11,Impostazioni!$B$10)) | Q8: =IF(Calendario!$J$7="","","Ob. "&IFERROR(VLOOKUP(Calendario!$J$7,Impostazioni!$A$25:$J$36,5,FALSE()),"?")&" · peso "&IF(Calendario!$F$7=2,Impostazioni!$B$11,Impostazioni!$B$10)) | W8: =IF(Calendario!$K$7="","","Ob. "&IFERROR(VLOOKUP(Calendario!$K$7,Impostazioni!$A$25:$J$36,5,FALSE()),"?")&" · peso "&IF(Calendario!$F$7=2,Impostazioni!$B$11,Impostazioni!$B$10))
A9: Indicatori (tocca → rubrica) | E9: =IF(Calendario!$H$7="","",IFERROR(HYPERLINK("#Rubriche!C"&(MATCH(Calendario!$H$7,Rubriche!$A$1:$A$1000,0)+0),VLOOKUP(Calendario!$H$7,Impostazioni!$A$25:$J$36,7,FALSE())),"")) -> Traiettorie | F9: =IF(Calendario!$H$7="","",IFERROR(HYPERLINK("#Rubriche!C"&(MATCH(Calendario!$H$7,Rubriche!$A$1:$A$1000,0)+1),VLOOKUP(Calendario!$H$7,Impostazioni!$A$25:$J$36,8,FALSE())),"")) -> Distanze e velocità | G9: =IF(Calendario!$H$7="","",IFERROR(HYPERLINK("#Rubriche!C"&(MATCH(Calendario!$H$7,Rubriche!$A$1:$A$1000,0)+2),VLOOKUP(Calendario!$H$7,Impostazioni!$A$25:$J$36,9,FALSE())),"")) -> Ritmi esecutivi | H9: =IF(Calendario!$H$7="","",IFERROR(HYPERLINK("#Rubriche!C"&(MATCH(Calendario!$H$7,Rubriche!$A$1:$A$1000,0)+3),VLOOKUP(Calendario!$H$7,Impostazioni!$A$25:$J$36,10,FALSE())),"")) -> Organizzazione con gli altri | K9: =IF(Calendario!$I$7="","",IFERROR(HYPERLINK("#Rubriche!C"&(MATCH(Calendario!$I$7,Rubriche!$A$1:$A$1000,0)+0),VLOOKUP(Calendario!$I$7,Impostazioni!$A$25:$J$36,7,FALSE())),"")) | L9: =IF(Calendario!$I$7="","",IFERROR(HYPERLINK("#Rubriche!C"&(MATCH(Calendario!$I$7,Rubriche!$A$1:$A$1000,0)+1),VLOOKUP(Calendario!$I$7,Impostazioni!$A$25:$J$36,8,FALSE())),"")) | M9: =IF(Calendario!$I$7="","",IFERROR(HYPERLINK("#Rubriche!C"&(MATCH(Calendario!$I$7,Rubriche!$A$1:$A$1000,0)+2),VLOOKUP(Calendario!$I$7,Impostazioni!$A$25:$J$36,9,FALSE())),"")) | N9: =IF(Calendario!$I$7="","",IFERROR(HYPERLINK("#Rubriche!C"&(MATCH(Calendario!$I$7,Rubriche!$A$1:$A$1000,0)+3),VLOOKUP(Calendario!$I$7,Impostazioni!$A$25:$J$36,10,FALSE())),"")) | Q9: =IF(Calendario!$J$7="","",IFERROR(HYPERLINK("#Rubriche!C"&(MATCH(Calendario!$J$7,Rubriche!$A$1:$A$1000,0)+0),VLOOKUP(Calendario!$J$7,Impostazioni!$A$25:$J$36,7,FALSE())),"")) | R9: =IF(Calendario!$J$7="","",IFERROR(HYPERLINK("#Rubriche!C"&(MATCH(Calendario!$J$7,Rubriche!$A$1:$A$1000,0)+1),VLOOKUP(Calendario!$J$7,Impostazioni!$A$25:$J$36,8,FALSE())),"")) | S9: =IF(Calendario!$J$7="","",IFERROR(HYPERLINK("#Rubriche!C"&(MATCH(Calendario!$J$7,Rubriche!$A$1:$A$1000,0)+2),VLOOKUP(Calendario!$J$7,Impostazioni!$A$25:$J$36,9,FALSE())),"")) | T9: =IF(Calendario!$J$7="","",IFERROR(HYPERLINK("#Rubriche!C"&(MATCH(Calendario!$J$7,Rubriche!$A$1:$A$1000,0)+3),VLOOKUP(Calendario!$J$7,Impostazioni!$A$25:$J$36,10,FALSE())),"")) | W9: =IF(Calendario!$K$7="","",IFERROR(HYPERLINK("#Rubriche!C"&(MATCH(Calendario!$K$7,Rubriche!$A$1:$A$1000,0)+0),VLOOKUP(Calendario!$K$7,Impostazioni!$A$25:$J$36,7,FALSE())),"")) | X9: =IF(Calendario!$K$7="","",IFERROR(HYPERLINK("#Rubriche!C"&(MATCH(Calendario!$K$7,Rubriche!$A$1:$A$1000,0)+1),VLOOKUP(Calendario!$K$7,Impostazioni!$A$25:$J$36,8,FALSE())),"")) | Y9: =IF(Calendario!$K$7="","",IFERROR(HYPERLINK("#Rubriche!C"&(MATCH(Calendario!$K$7,Rubriche!$A$1:$A$1000,0)+2),VLOOKUP(Calendario!$K$7,Impostazioni!$A$25:$J$36,9,FALSE())),"")) | Z9: =IF(Calendario!$K$7="","",IFERROR(HYPERLINK("#Rubriche!C"&(MATCH(Calendario!$K$7,Rubriche!$A$1:$A$1000,0)+3),VLOOKUP(Calendario!$K$7,Impostazioni!$A$25:$J$36,10,FALSE())),""))
A10: N° | B10: Alunno | C10: Stato | D10: Recuperata il | E10: I1 | F10: I2 | G10: I3 | H10: I4 | I10: VOTO | J10: GIUDIZIO (Argo) | K10: I1 | L10: I2 | M10: I3 | N10: I4 | O10: VOTO | P10: GIUDIZIO (Argo) | Q10: I1 | R10: I2 | S10: I3 | T10: I4 | U10: VOTO | V10: GIUDIZIO (Argo) | W10: I1 | X10: I2 | Y10: I3 | Z10: I4 | AA10: VOTO | AB10: GIUDIZIO (Argo)
A11: 1 | B11: =IFERROR(INDEX(Alunni!$C$1:$C$1000,MATCH($A11,Alunni!$A$1:$A$1000,0))&"","") -> Rossi Mario (esempio) | E11: 8 | F11: 8 | G11: 7 | I11: =IF(COUNT(E11:H11)=0,"",ROUND(AVERAGE(E11:H11),0)) -> 8 | J11: =IF(I11="","",LOOKUP(I11,Impostazioni!$E$4:$E$9,Impostazioni!$F$4:$F$9)) -> Buono | O11: =IF(COUNT(K11:N11)=0,"",ROUND(AVERAGE(K11:N11),0)) | P11: =IF(O11="","",LOOKUP(O11,Impostazioni!$E$4:$E$9,Impostazioni!$F$4:$F$9)) | U11: =IF(COUNT(Q11:T11)=0,"",ROUND(AVERAGE(Q11:T11),0)) | V11: =IF(U11="","",LOOKUP(U11,Impostazioni!$E$4:$E$9,Impostazioni!$F$4:$F$9)) | AA11: =IF(COUNT(W11:Z11)=0,"",ROUND(AVERAGE(W11:Z11),0)) | AB11: =IF(AA11="","",LOOKUP(AA11,Impostazioni!$E$4:$E$9,Impostazioni!$F$4:$F$9))
A12: 2 | B12: =IFERROR(INDEX(Alunni!$C$1:$C$1000,MATCH($A12,Alunni!$A$1:$A$1000,0))&"","") -> Bianchi Anna (esempio) | E12: 7 | F12: 7 | I12: =IF(COUNT(E12:H12)=0,"",ROUND(AVERAGE(E12:H12),0)) -> 7 | J12: =IF(I12="","",LOOKUP(I12,Impostazioni!$E$4:$E$9,Impostazioni!$F$4:$F$9)) -> Discreto | O12: =IF(COUNT(K12:N12)=0,"",ROUND(AVERAGE(K12:N12),0)) | P12: =IF(O12="","",LOOKUP(O12,Impostazioni!$E$4:$E$9,Impostazioni!$F$4:$F$9)) | U12: =IF(COUNT(Q12:T12)=0,"",ROUND(AVERAGE(Q12:T12),0)) | V12: =IF(U12="","",LOOKUP(U12,Impostazioni!$E$4:$E$9,Impostazioni!$F$4:$F$9)) | AA12: =IF(COUNT(W12:Z12)=0,"",ROUND(AVERAGE(W12:Z12),0)) | AB12: =IF(AA12="","",LOOKUP(AA12,Impostazioni!$E$4:$E$9,Impostazioni!$F$4:$F$9))
A13: 3 | B13: =IFERROR(INDEX(Alunni!$C$1:$C$1000,MATCH($A13,Alunni!$A$1:$A$1000,0))&"","") -> Verdi Luca (esempio) | I13: =IF(COUNT(E13:H13)=0,"",ROUND(AVERAGE(E13:H13),0)) | J13: =IF(I13="","",LOOKUP(I13,Impostazioni!$E$4:$E$9,Impostazioni!$F$4:$F$9)) | O13: =IF(COUNT(K13:N13)=0,"",ROUND(AVERAGE(K13:N13),0)) | P13: =IF(O13="","",LOOKUP(O13,Impostazioni!$E$4:$E$9,Impostazioni!$F$4:$F$9)) | U13: =IF(COUNT(Q13:T13)=0,"",ROUND(AVERAGE(Q13:T13),0)) | V13: =IF(U13="","",LOOKUP(U13,Impostazioni!$E$4:$E$9,Impostazioni!$F$4:$F$9)) | AA13: =IF(COUNT(W13:Z13)=0,"",ROUND(AVERAGE(W13:Z13),0)) | AB13: =IF(AA13="","",LOOKUP(AA13,Impostazioni!$E$4:$E$9,Impostazioni!$F$4:$F$9))
A14: 4 | B14: =IFERROR(INDEX(Alunni!$C$1:$C$1000,MATCH($A14,Alunni!$A$1:$A$1000,0))&"","") | I14: =IF(COUNT(E14:H14)=0,"",ROUND(AVERAGE(E14:H14),0)) | J14: =IF(I14="","",LOOKUP(I14,Impostazioni!$E$4:$E$9,Impostazioni!$F$4:$F$9)) | O14: =IF(COUNT(K14:N14)=0,"",ROUND(AVERAGE(K14:N14),0)) | P14: =IF(O14="","",LOOKUP(O14,Impostazioni!$E$4:$E$9,Impostazioni!$F$4:$F$9)) | U14: =IF(COUNT(Q14:T14)=0,"",ROUND(AVERAGE(Q14:T14),0)) | V14: =IF(U14="","",LOOKUP(U14,Impostazioni!$E$4:$E$9,Impostazioni!$F$4:$F$9)) | AA14: =IF(COUNT(W14:Z14)=0,"",ROUND(AVERAGE(W14:Z14),0)) | AB14: =IF(AA14="","",LOOKUP(AA14,Impostazioni!$E$4:$E$9,Impostazioni!$F$4:$F$9))
A15: 5 | B15: =IFERROR(INDEX(Alunni!$C$1:$C$1000,MATCH($A15,Alunni!$A$1:$A$1000,0))&"","") | I15: =IF(COUNT(E15:H15)=0,"",ROUND(AVERAGE(E15:H15),0)) | J15: =IF(I15="","",LOOKUP(I15,Impostazioni!$E$4:$E$9,Impostazioni!$F$4:$F$9)) | O15: =IF(COUNT(K15:N15)=0,"",ROUND(AVERAGE(K15:N15),0)) | P15: =IF(O15="","",LOOKUP(O15,Impostazioni!$E$4:$E$9,Impostazioni!$F$4:$F$9)) | U15: =IF(COUNT(Q15:T15)=0,"",ROUND(AVERAGE(Q15:T15),0)) | V15: =IF(U15="","",LOOKUP(U15,Impostazioni!$E$4:$E$9,Impostazioni!$F$4:$F$9)) | AA15: =IF(COUNT(W15:Z15)=0,"",ROUND(AVERAGE(W15:Z15),0)) | AB15: =IF(AA15="","",LOOKUP(AA15,Impostazioni!$E$4:$E$9,Impostazioni!$F$4:$F$9))
A16: 6 | B16: =IFERROR(INDEX(Alunni!$C$1:$C$1000,MATCH($A16,Alunni!$A$1:$A$1000,0))&"","") | I16: =IF(COUNT(E16:H16)=0,"",ROUND(AVERAGE(E16:H16),0)) | J16: =IF(I16="","",LOOKUP(I16,Impostazioni!$E$4:$E$9,Impostazioni!$F$4:$F$9)) | O16: =IF(COUNT(K16:N16)=0,"",ROUND(AVERAGE(K16:N16),0)) | P16: =IF(O16="","",LOOKUP(O16,Impostazioni!$E$4:$E$9,Impostazioni!$F$4:$F$9)) | U16: =IF(COUNT(Q16:T16)=0,"",ROUND(AVERAGE(Q16:T16),0)) | V16: =IF(U16="","",LOOKUP(U16,Impostazioni!$E$4:$E$9,Impostazioni!$F$4:$F$9)) | AA16: =IF(COUNT(W16:Z16)=0,"",ROUND(AVERAGE(W16:Z16),0)) | AB16: =IF(AA16="","",LOOKUP(AA16,Impostazioni!$E$4:$E$9,Impostazioni!$F$4:$F$9))
A17: 7 | B17: =IFERROR(INDEX(Alunni!$C$1:$C$1000,MATCH($A17,Alunni!$A$1:$A$1000,0))&"","") | I17: =IF(COUNT(E17:H17)=0,"",ROUND(AVERAGE(E17:H17),0)) | J17: =IF(I17="","",LOOKUP(I17,Impostazioni!$E$4:$E$9,Impostazioni!$F$4:$F$9)) | O17: =IF(COUNT(K17:N17)=0,"",ROUND(AVERAGE(K17:N17),0)) | P17: =IF(O17="","",LOOKUP(O17,Impostazioni!$E$4:$E$9,Impostazioni!$F$4:$F$9)) | U17: =IF(COUNT(Q17:T17)=0,"",ROUND(AVERAGE(Q17:T17),0)) | V17: =IF(U17="","",LOOKUP(U17,Impostazioni!$E$4:$E$9,Impostazioni!$F$4:$F$9)) | AA17: =IF(COUNT(W17:Z17)=0,"",ROUND(AVERAGE(W17:Z17),0)) | AB17: =IF(AA17="","",LOOKUP(AA17,Impostazioni!$E$4:$E$9,Impostazioni!$F$4:$F$9))
A18: 8 | B18: =IFERROR(INDEX(Alunni!$C$1:$C$1000,MATCH($A18,Alunni!$A$1:$A$1000,0))&"","") | I18: =IF(COUNT(E18:H18)=0,"",ROUND(AVERAGE(E18:H18),0)) | J18: =IF(I18="","",LOOKUP(I18,Impostazioni!$E$4:$E$9,Impostazioni!$F$4:$F$9)) | O18: =IF(COUNT(K18:N18)=0,"",ROUND(AVERAGE(K18:N18),0)) | P18: =IF(O18="","",LOOKUP(O18,Impostazioni!$E$4:$E$9,Impostazioni!$F$4:$F$9)) | U18: =IF(COUNT(Q18:T18)=0,"",ROUND(AVERAGE(Q18:T18),0)) | V18: =IF(U18="","",LOOKUP(U18,Impostazioni!$E$4:$E$9,Impostazioni!$F$4:$F$9)) | AA18: =IF(COUNT(W18:Z18)=0,"",ROUND(AVERAGE(W18:Z18),0)) | AB18: =IF(AA18="","",LOOKUP(AA18,Impostazioni!$E$4:$E$9,Impostazioni!$F$4:$F$9))
A19: 9 | B19: =IFERROR(INDEX(Alunni!$C$1:$C$1000,MATCH($A19,Alunni!$A$1:$A$1000,0))&"","") | I19: =IF(COUNT(E19:H19)=0,"",ROUND(AVERAGE(E19:H19),0)) | J19: =IF(I19="","",LOOKUP(I19,Impostazioni!$E$4:$E$9,Impostazioni!$F$4:$F$9)) | O19: =IF(COUNT(K19:N19)=0,"",ROUND(AVERAGE(K19:N19),0)) | P19: =IF(O19="","",LOOKUP(O19,Impostazioni!$E$4:$E$9,Impostazioni!$F$4:$F$9)) | U19: =IF(COUNT(Q19:T19)=0,"",ROUND(AVERAGE(Q19:T19),0)) | V19: =IF(U19="","",LOOKUP(U19,Impostazioni!$E$4:$E$9,Impostazioni!$F$4:$F$9)) | AA19: =IF(COUNT(W19:Z19)=0,"",ROUND(AVERAGE(W19:Z19),0)) | AB19: =IF(AA19="","",LOOKUP(AA19,Impostazioni!$E$4:$E$9,Impostazioni!$F$4:$F$9))
A20: 10 | B20: =IFERROR(INDEX(Alunni!$C$1:$C$1000,MATCH($A20,Alunni!$A$1:$A$1000,0))&"","") | I20: =IF(COUNT(E20:H20)=0,"",ROUND(AVERAGE(E20:H20),0)) | J20: =IF(I20="","",LOOKUP(I20,Impostazioni!$E$4:$E$9,Impostazioni!$F$4:$F$9)) | O20: =IF(COUNT(K20:N20)=0,"",ROUND(AVERAGE(K20:N20),0)) | P20: =IF(O20="","",LOOKUP(O20,Impostazioni!$E$4:$E$9,Impostazioni!$F$4:$F$9)) | U20: =IF(COUNT(Q20:T20)=0,"",ROUND(AVERAGE(Q20:T20),0)) | V20: =IF(U20="","",LOOKUP(U20,Impostazioni!$E$4:$E$9,Impostazioni!$F$4:$F$9)) | AA20: =IF(COUNT(W20:Z20)=0,"",ROUND(AVERAGE(W20:Z20),0)) | AB20: =IF(AA20="","",LOOKUP(AA20,Impostazioni!$E$4:$E$9,Impostazioni!$F$4:$F$9))
A21: 11 | B21: =IFERROR(INDEX(Alunni!$C$1:$C$1000,MATCH($A21,Alunni!$A$1:$A$1000,0))&"","") | I21: =IF(COUNT(E21:H21)=0,"",ROUND(AVERAGE(E21:H21),0)) | J21: =IF(I21="","",LOOKUP(I21,Impostazioni!$E$4:$E$9,Impostazioni!$F$4:$F$9)) | O21: =IF(COUNT(K21:N21)=0,"",ROUND(AVERAGE(K21:N21),0)) | P21: =IF(O21="","",LOOKUP(O21,Impostazioni!$E$4:$E$9,Impostazioni!$F$4:$F$9)) | U21: =IF(COUNT(Q21:T21)=0,"",ROUND(AVERAGE(Q21:T21),0)) | V21: =IF(U21="","",LOOKUP(U21,Impostazioni!$E$4:$E$9,Impostazioni!$F$4:$F$9)) | AA21: =IF(COUNT(W21:Z21)=0,"",ROUND(AVERAGE(W21:Z21),0)) | AB21: =IF(AA21="","",LOOKUP(AA21,Impostazioni!$E$4:$E$9,Impostazioni!$F$4:$F$9))
A22: 12 | B22: =IFERROR(INDEX(Alunni!$C$1:$C$1000,MATCH($A22,Alunni!$A$1:$A$1000,0))&"","") | I22: =IF(COUNT(E22:H22)=0,"",ROUND(AVERAGE(E22:H22),0)) | J22: =IF(I22="","",LOOKUP(I22,Impostazioni!$E$4:$E$9,Impostazioni!$F$4:$F$9)) | O22: =IF(COUNT(K22:N22)=0,"",ROUND(AVERAGE(K22:N22),0)) | P22: =IF(O22="","",LOOKUP(O22,Impostazioni!$E$4:$E$9,Impostazioni!$F$4:$F$9)) | U22: =IF(COUNT(Q22:T22)=0,"",ROUND(AVERAGE(Q22:T22),0)) | V22: =IF(U22="","",LOOKUP(U22,Impostazioni!$E$4:$E$9,Impostazioni!$F$4:$F$9)) | AA22: =IF(COUNT(W22:Z22)=0,"",ROUND(AVERAGE(W22:Z22),0)) | AB22: =IF(AA22="","",LOOKUP(AA22,Impostazioni!$E$4:$E$9,Impostazioni!$F$4:$F$9))
A23: 13 | B23: =IFERROR(INDEX(Alunni!$C$1:$C$1000,MATCH($A23,Alunni!$A$1:$A$1000,0))&"","") | I23: =IF(COUNT(E23:H23)=0,"",ROUND(AVERAGE(E23:H23),0)) | J23: =IF(I23="","",LOOKUP(I23,Impostazioni!$E$4:$E$9,Impostazioni!$F$4:$F$9)) | O23: =IF(COUNT(K23:N23)=0,"",ROUND(AVERAGE(K23:N23),0)) | P23: =IF(O23="","",LOOKUP(O23,Impostazioni!$E$4:$E$9,Impostazioni!$F$4:$F$9)) | U23: =IF(COUNT(Q23:T23)=0,"",ROUND(AVERAGE(Q23:T23),0)) | V23: =IF(U23="","",LOOKUP(U23,Impostazioni!$E$4:$E$9,Impostazioni!$F$4:$F$9)) | AA23: =IF(COUNT(W23:Z23)=0,"",ROUND(AVERAGE(W23:Z23),0)) | AB23: =IF(AA23="","",LOOKUP(AA23,Impostazioni!$E$4:$E$9,Impostazioni!$F$4:$F$9))
A24: 14 | B24: =IFERROR(INDEX(Alunni!$C$1:$C$1000,MATCH($A24,Alunni!$A$1:$A$1000,0))&"","") | I24: =IF(COUNT(E24:H24)=0,"",ROUND(AVERAGE(E24:H24),0)) | J24: =IF(I24="","",LOOKUP(I24,Impostazioni!$E$4:$E$9,Impostazioni!$F$4:$F$9)) | O24: =IF(COUNT(K24:N24)=0,"",ROUND(AVERAGE(K24:N24),0)) | P24: =IF(O24="","",LOOKUP(O24,Impostazioni!$E$4:$E$9,Impostazioni!$F$4:$F$9)) | U24: =IF(COUNT(Q24:T24)=0,"",ROUND(AVERAGE(Q24:T24),0)) | V24: =IF(U24="","",LOOKUP(U24,Impostazioni!$E$4:$E$9,Impostazioni!$F$4:$F$9)) | AA24: =IF(COUNT(W24:Z24)=0,"",ROUND(AVERAGE(W24:Z24),0)) | AB24: =IF(AA24="","",LOOKUP(AA24,Impostazioni!$E$4:$E$9,Impostazioni!$F$4:$F$9))
... A40: 30 | B40: =IFERROR(INDEX(Alunni!$C$1:$C$1000,MATCH($A40,Alunni!$A$1:$A$1000,0))&"","") | I40: =IF(COUNT(E40:H40)=0,"",ROUND(AVERAGE(E40:H40),0)) | J40: =IF(I40="","",LOOKUP(I40,Impostazioni!$E$4:$E$9,Impostazioni!$F$4:$F$9)) | O40: =IF(COUNT(K40:N40)=0,"",ROUND(AVERAGE(K40:N40),0)) | P40: =IF(O40="","",LOOKUP(O40,Impostazioni!$E$4:$E$9,Impostazioni!$F$4:$F$9)) | U40: =IF(COUNT(Q40:T40)=0,"",ROUND(AVERAGE(Q40:T40),0)) | V40: =IF(U40="","",LOOKUP(U40,Impostazioni!$E$4:$E$9,Impostazioni!$F$4:$F$9)) | AA40: =IF(COUNT(W40:Z40)=0,"",ROUND(AVERAGE(W40:Z40),0)) | AB40: =IF(AA40="","",LOOKUP(AA40,Impostazioni!$E$4:$E$9,Impostazioni!$F$4:$F$9))
A42: =Calendario!B8&" · "&IF(Calendario!G8="","(descrizione da Calendario)",Calendario!G8)&" · "&IF(Calendario!E8="","data da fissare",CHOOSE(WEEKDAY(Calendario!E8,2),"lunedì","martedì","mercoledì","giovedì","venerdì","sabato","domenica")&" "&TEXT(DAY(Calendario!E8),"00")&"/"&TEXT(MONTH(Calendario!E8),"00")&"/"&YEAR(Calendario!E8)) -> Q1-G02 · Progetto basket – osservazione (lezioni con l'esperto) · lunedì 26/10/2026
A43: Sotto-obiettivo | E43: =IF(Calendario!$H$8="","— libero —",Calendario!$H$8&" "&IFERROR(VLOOKUP(Calendario!$H$8,Impostazioni!$A$25:$J$36,3,FALSE()),"")) -> 3.1 Modalità esecutive gioco-sport | K43: =IF(Calendario!$I$8="","— libero —",Calendario!$I$8&" "&IFERROR(VLOOKUP(Calendario!$I$8,Impostazioni!$A$25:$J$36,3,FALSE()),"")) -> 3.3 Regole, sconfitta e vittoria | Q43: =IF(Calendario!$J$8="","— libero —",Calendario!$J$8&" "&IFERROR(VLOOKUP(Calendario!$J$8,Impostazioni!$A$25:$J$36,3,FALSE()),"")) -> — libero — | W43: =IF(Calendario!$K$8="","— libero —",Calendario!$K$8&" "&IFERROR(VLOOKUP(Calendario!$K$8,Impostazioni!$A$25:$J$36,3,FALSE()),"")) -> — libero —
A44: Concorre a | E44: =IF(Calendario!$H$8="","","Ob. "&IFERROR(VLOOKUP(Calendario!$H$8,Impostazioni!$A$25:$J$36,5,FALSE()),"?")&" · peso "&IF(Calendario!$F$8=2,Impostazioni!$B$11,Impostazioni!$B$10)) -> Ob. B · peso 1 | K44: =IF(Calendario!$I$8="","","Ob. "&IFERROR(VLOOKUP(Calendario!$I$8,Impostazioni!$A$25:$J$36,5,FALSE()),"?")&" · peso "&IF(Calendario!$F$8=2,Impostazioni!$B$11,Impostazioni!$B$10)) -> Ob. B · peso 1 | Q44: =IF(Calendario!$J$8="","","Ob. "&IFERROR(VLOOKUP(Calendario!$J$8,Impostazioni!$A$25:$J$36,5,FALSE()),"?")&" · peso "&IF(Calendario!$F$8=2,Impostazioni!$B$11,Impostazioni!$B$10)) | W44: =IF(Calendario!$K$8="","","Ob. "&IFERROR(VLOOKUP(Calendario!$K$8,Impostazioni!$A$25:$J$36,5,FALSE()),"?")&" · peso "&IF(Calendario!$F$8=2,Impostazioni!$B$11,Impostazioni!$B$10))
A45: Indicatori (tocca → rubrica) | E45: =IF(Calendario!$H$8="","",IFERROR(HYPERLINK("#Rubriche!C"&(MATCH(Calendario!$H$8,Rubriche!$A$1:$A$1000,0)+0),VLOOKUP(Calendario!$H$8,Impostazioni!$A$25:$J$36,7,FALSE())),"")) -> Gesti tecnici | F45: =IF(Calendario!$H$8="","",IFERROR(HYPERLINK("#Rubriche!C"&(MATCH(Calendario!$H$8,Rubriche!$A$1:$A$1000,0)+1),VLOOKUP(Calendario!$H$8,Impostazioni!$A$25:$J$36,8,FALSE())),"")) -> Regole specifiche | G45: =IF(Calendario!$H$8="","",IFERROR(HYPERLINK("#Rubriche!C"&(MATCH(Calendario!$H$8,Rubriche!$A$1:$A$1000,0)+2),VLOOKUP(Calendario!$H$8,Impostazioni!$A$25:$J$36,9,FALSE())),"")) -> Scelte di gioco | H45: =IF(Calendario!$H$8="","",IFERROR(HYPERLINK("#Rubriche!C"&(MATCH(Calendario!$H$8,Rubriche!$A$1:$A$1000,0)+3),VLOOKUP(Calendario!$H$8,Impostazioni!$A$25:$J$36,10,FALSE())),"")) -> Ruolo in campo | K45: =IF(Calendario!$I$8="","",IFERROR(HYPERLINK("#Rubriche!C"&(MATCH(Calendario!$I$8,Rubriche!$A$1:$A$1000,0)+0),VLOOKUP(Calendario!$I$8,Impostazioni!$A$25:$J$36,7,FALSE())),"")) -> Regole nella competizione | L45: =IF(Calendario!$I$8="","",IFERROR(HYPERLINK("#Rubriche!C"&(MATCH(Calendario!$I$8,Rubriche!$A$1:$A$1000,0)+1),VLOOKUP(Calendario!$I$8,Impostazioni!$A$25:$J$36,8,FALSE())),"")) -> Fair play | M45: =IF(Calendario!$I$8="","",IFERROR(HYPERLINK("#Rubriche!C"&(MATCH(Calendario!$I$8,Rubriche!$A$1:$A$1000,0)+2),VLOOKUP(Calendario!$I$8,Impostazioni!$A$25:$J$36,9,FALSE())),"")) -> Gestione dell'esito | N45: =IF(Calendario!$I$8="","",IFERROR(HYPERLINK("#Rubriche!C"&(MATCH(Calendario!$I$8,Rubriche!$A$1:$A$1000,0)+3),VLOOKUP(Calendario!$I$8,Impostazioni!$A$25:$J$36,10,FALSE())),"")) -> Responsabilità | Q45: =IF(Calendario!$J$8="","",IFERROR(HYPERLINK("#Rubriche!C"&(MATCH(Calendario!$J$8,Rubriche!$A$1:$A$1000,0)+0),VLOOKUP(Calendario!$J$8,Impostazioni!$A$25:$J$36,7,FALSE())),"")) | R45: =IF(Calendario!$J$8="","",IFERROR(HYPERLINK("#Rubriche!C"&(MATCH(Calendario!$J$8,Rubriche!$A$1:$A$1000,0)+1),VLOOKUP(Calendario!$J$8,Impostazioni!$A$25:$J$36,8,FALSE())),"")) | S45: =IF(Calendario!$J$8="","",IFERROR(HYPERLINK("#Rubriche!C"&(MATCH(Calendario!$J$8,Rubriche!$A$1:$A$1000,0)+2),VLOOKUP(Calendario!$J$8,Impostazioni!$A$25:$J$36,9,FALSE())),"")) | T45: =IF(Calendario!$J$8="","",IFERROR(HYPERLINK("#Rubriche!C"&(MATCH(Calendario!$J$8,Rubriche!$A$1:$A$1000,0)+3),VLOOKUP(Calendario!$J$8,Impostazioni!$A$25:$J$36,10,FALSE())),"")) | W45: =IF(Calendario!$K$8="","",IFERROR(HYPERLINK("#Rubriche!C"&(MATCH(Calendario!$K$8,Rubriche!$A$1:$A$1000,0)+0),VLOOKUP(Calendario!$K$8,Impostazioni!$A$25:$J$36,7,FALSE())),"")) | X45: =IF(Calendario!$K$8="","",IFERROR(HYPERLINK("#Rubriche!C"&(MATCH(Calendario!$K$8,Rubriche!$A$1:$A$1000,0)+1),VLOOKUP(Calendario!$K$8,Impostazioni!$A$25:$J$36,8,FALSE())),"")) | Y45: =IF(Calendario!$K$8="","",IFERROR(HYPERLINK("#Rubriche!C"&(MATCH(Calendario!$K$8,Rubriche!$A$1:$A$1000,0)+2),VLOOKUP(Calendario!$K$8,Impostazioni!$A$25:$J$36,9,FALSE())),"")) | Z45: =IF(Calendario!$K$8="","",IFERROR(HYPERLINK("#Rubriche!C"&(MATCH(Calendario!$K$8,Rubriche!$A$1:$A$1000,0)+3),VLOOKUP(Calendario!$K$8,Impostazioni!$A$25:$J$36,10,FALSE())),""))
A46: N° | B46: Alunno | C46: Stato | D46: Recuperata il | E46: I1 | F46: I2 | G46: I3 | H46: I4 | I46: VOTO | J46: GIUDIZIO (Argo) | K46: I1 | L46: I2 | M46: I3 | N46: I4 | O46: VOTO | P46: GIUDIZIO (Argo) | Q46: I1 | R46: I2 | S46: I3 | T46: I4 | U46: VOTO | V46: GIUDIZIO (Argo) | W46: I1 | X46: I2 | Y46: I3 | Z46: I4 | AA46: VOTO | AB46: GIUDIZIO (Argo)
A47: 1 | B47: =IFERROR(INDEX(Alunni!$C$1:$C$1000,MATCH($A47,Alunni!$A$1:$A$1000,0))&"","") -> Rossi Mario (esempio) | E47: 8 | F47: 9 | G47: 8 | H47: 8 | I47: =IF(COUNT(E47:H47)=0,"",ROUND(AVERAGE(E47:H47),0)) -> 8 | J47: =IF(I47="","",LOOKUP(I47,Impostazioni!$E$4:$E$9,Impostazioni!$F$4:$F$9)) -> Buono | K47: 8 | L47: 8 | M47: 9 | N47: 8 | O47: =IF(COUNT(K47:N47)=0,"",ROUND(AVERAGE(K47:N47),0)) -> 8 | P47: =IF(O47="","",LOOKUP(O47,Impostazioni!$E$4:$E$9,Impostazioni!$F$4:$F$9)) -> Buono | U47: =IF(COUNT(Q47:T47)=0,"",ROUND(AVERAGE(Q47:T47),0)) | V47: =IF(U47="","",LOOKUP(U47,Impostazioni!$E$4:$E$9,Impostazioni!$F$4:$F$9)) | AA47: =IF(COUNT(W47:Z47)=0,"",ROUND(AVERAGE(W47:Z47),0)) | AB47: =IF(AA47="","",LOOKUP(AA47,Impostazioni!$E$4:$E$9,Impostazioni!$F$4:$F$9))
A48: 2 | B48: =IFERROR(INDEX(Alunni!$C$1:$C$1000,MATCH($A48,Alunni!$A$1:$A$1000,0))&"","") -> Bianchi Anna (esempio) | E48: 9 | F48: 9 | G48: 9 | H48: 8 | I48: =IF(COUNT(E48:H48)=0,"",ROUND(AVERAGE(E48:H48),0)) -> 9 | J48: =IF(I48="","",LOOKUP(I48,Impostazioni!$E$4:$E$9,Impostazioni!$F$4:$F$9)) -> Distinto | K48: 8 | L48: 8 | M48: 8 | N48: 8 | O48: =IF(COUNT(K48:N48)=0,"",ROUND(AVERAGE(K48:N48),0)) -> 8 | P48: =IF(O48="","",LOOKUP(O48,Impostazioni!$E$4:$E$9,Impostazioni!$F$4:$F$9)) -> Buono | U48: =IF(COUNT(Q48:T48)=0,"",ROUND(AVERAGE(Q48:T48),0)) | V48: =IF(U48="","",LOOKUP(U48,Impostazioni!$E$4:$E$9,Impostazioni!$F$4:$F$9)) | AA48: =IF(COUNT(W48:Z48)=0,"",ROUND(AVERAGE(W48:Z48),0)) | AB48: =IF(AA48="","",LOOKUP(AA48,Impostazioni!$E$4:$E$9,Impostazioni!$F$4:$F$9))
A49: 3 | B49: =IFERROR(INDEX(Alunni!$C$1:$C$1000,MATCH($A49,Alunni!$A$1:$A$1000,0))&"","") -> Verdi Luca (esempio) | I49: =IF(COUNT(E49:H49)=0,"",ROUND(AVERAGE(E49:H49),0)) | J49: =IF(I49="","",LOOKUP(I49,Impostazioni!$E$4:$E$9,Impostazioni!$F$4:$F$9)) | O49: =IF(COUNT(K49:N49)=0,"",ROUND(AVERAGE(K49:N49),0)) | P49: =IF(O49="","",LOOKUP(O49,Impostazioni!$E$4:$E$9,Impostazioni!$F$4:$F$9)) | U49: =IF(COUNT(Q49:T49)=0,"",ROUND(AVERAGE(Q49:T49),0)) | V49: =IF(U49="","",LOOKUP(U49,Impostazioni!$E$4:$E$9,Impostazioni!$F$4:$F$9)) | AA49: =IF(COUNT(W49:Z49)=0,"",ROUND(AVERAGE(W49:Z49),0)) | AB49: =IF(AA49="","",LOOKUP(AA49,Impostazioni!$E$4:$E$9,Impostazioni!$F$4:$F$9))
A50: 4 | B50: =IFERROR(INDEX(Alunni!$C$1:$C$1000,MATCH($A50,Alunni!$A$1:$A$1000,0))&"","") | I50: =IF(COUNT(E50:H50)=0,"",ROUND(AVERAGE(E50:H50),0)) | J50: =IF(I50="","",LOOKUP(I50,Impostazioni!$E$4:$E$9,Impostazioni!$F$4:$F$9)) | O50: =IF(COUNT(K50:N50)=0,"",ROUND(AVERAGE(K50:N50),0)) | P50: =IF(O50="","",LOOKUP(O50,Impostazioni!$E$4:$E$9,Impostazioni!$F$4:$F$9)) | U50: =IF(COUNT(Q50:T50)=0,"",ROUND(AVERAGE(Q50:T50),0)) | V50: =IF(U50="","",LOOKUP(U50,Impostazioni!$E$4:$E$9,Impostazioni!$F$4:$F$9)) | AA50: =IF(COUNT(W50:Z50)=0,"",ROUND(AVERAGE(W50:Z50),0)) | AB50: =IF(AA50="","",LOOKUP(AA50,Impostazioni!$E$4:$E$9,Impostazioni!$F$4:$F$9))
A51: 5 | B51: =IFERROR(INDEX(Alunni!$C$1:$C$1000,MATCH($A51,Alunni!$A$1:$A$1000,0))&"","") | I51: =IF(COUNT(E51:H51)=0,"",ROUND(AVERAGE(E51:H51),0)) | J51: =IF(I51="","",LOOKUP(I51,Impostazioni!$E$4:$E$9,Impostazioni!$F$4:$F$9)) | O51: =IF(COUNT(K51:N51)=0,"",ROUND(AVERAGE(K51:N51),0)) | P51: =IF(O51="","",LOOKUP(O51,Impostazioni!$E$4:$E$9,Impostazioni!$F$4:$F$9)) | U51: =IF(COUNT(Q51:T51)=0,"",ROUND(AVERAGE(Q51:T51),0)) | V51: =IF(U51="","",LOOKUP(U51,Impostazioni!$E$4:$E$9,Impostazioni!$F$4:$F$9)) | AA51: =IF(COUNT(W51:Z51)=0,"",ROUND(AVERAGE(W51:Z51),0)) | AB51: =IF(AA51="","",LOOKUP(AA51,Impostazioni!$E$4:$E$9,Impostazioni!$F$4:$F$9))
A52: 6 | B52: =IFERROR(INDEX(Alunni!$C$1:$C$1000,MATCH($A52,Alunni!$A$1:$A$1000,0))&"","") | I52: =IF(COUNT(E52:H52)=0,"",ROUND(AVERAGE(E52:H52),0)) | J52: =IF(I52="","",LOOKUP(I52,Impostazioni!$E$4:$E$9,Impostazioni!$F$4:$F$9)) | O52: =IF(COUNT(K52:N52)=0,"",ROUND(AVERAGE(K52:N52),0)) | P52: =IF(O52="","",LOOKUP(O52,Impostazioni!$E$4:$E$9,Impostazioni!$F$4:$F$9)) | U52: =IF(COUNT(Q52:T52)=0,"",ROUND(AVERAGE(Q52:T52),0)) | V52: =IF(U52="","",LOOKUP(U52,Impostazioni!$E$4:$E$9,Impostazioni!$F$4:$F$9)) | AA52: =IF(COUNT(W52:Z52)=0,"",ROUND(AVERAGE(W52:Z52),0)) | AB52: =IF(AA52="","",LOOKUP(AA52,Impostazioni!$E$4:$E$9,Impostazioni!$F$4:$F$9))
A53: 7 | B53: =IFERROR(INDEX(Alunni!$C$1:$C$1000,MATCH($A53,Alunni!$A$1:$A$1000,0))&"","") | I53: =IF(COUNT(E53:H53)=0,"",ROUND(AVERAGE(E53:H53),0)) | J53: =IF(I53="","",LOOKUP(I53,Impostazioni!$E$4:$E$9,Impostazioni!$F$4:$F$9)) | O53: =IF(COUNT(K53:N53)=0,"",ROUND(AVERAGE(K53:N53),0)) | P53: =IF(O53="","",LOOKUP(O53,Impostazioni!$E$4:$E$9,Impostazioni!$F$4:$F$9)) | U53: =IF(COUNT(Q53:T53)=0,"",ROUND(AVERAGE(Q53:T53),0)) | V53: =IF(U53="","",LOOKUP(U53,Impostazioni!$E$4:$E$9,Impostazioni!$F$4:$F$9)) | AA53: =IF(COUNT(W53:Z53)=0,"",ROUND(AVERAGE(W53:Z53),0)) | AB53: =IF(AA53="","",LOOKUP(AA53,Impostazioni!$E$4:$E$9,Impostazioni!$F$4:$F$9))
A54: 8 | B54: =IFERROR(INDEX(Alunni!$C$1:$C$1000,MATCH($A54,Alunni!$A$1:$A$1000,0))&"","") | I54: =IF(COUNT(E54:H54)=0,"",ROUND(AVERAGE(E54:H54),0)) | J54: =IF(I54="","",LOOKUP(I54,Impostazioni!$E$4:$E$9,Impostazioni!$F$4:$F$9)) | O54: =IF(COUNT(K54:N54)=0,"",ROUND(AVERAGE(K54:N54),0)) | P54: =IF(O54="","",LOOKUP(O54,Impostazioni!$E$4:$E$9,Impostazioni!$F$4:$F$9)) | U54: =IF(COUNT(Q54:T54)=0,"",ROUND(AVERAGE(Q54:T54),0)) | V54: =IF(U54="","",LOOKUP(U54,Impostazioni!$E$4:$E$9,Impostazioni!$F$4:$F$9)) | AA54: =IF(COUNT(W54:Z54)=0,"",ROUND(AVERAGE(W54:Z54),0)) | AB54: =IF(AA54="","",LOOKUP(AA54,Impostazioni!$E$4:$E$9,Impostazioni!$F$4:$F$9))
A55: 9 | B55: =IFERROR(INDEX(Alunni!$C$1:$C$1000,MATCH($A55,Alunni!$A$1:$A$1000,0))&"","") | I55: =IF(COUNT(E55:H55)=0,"",ROUND(AVERAGE(E55:H55),0)) | J55: =IF(I55="","",LOOKUP(I55,Impostazioni!$E$4:$E$9,Impostazioni!$F$4:$F$9)) | O55: =IF(COUNT(K55:N55)=0,"",ROUND(AVERAGE(K55:N55),0)) | P55: =IF(O55="","",LOOKUP(O55,Impostazioni!$E$4:$E$9,Impostazioni!$F$4:$F$9)) | U55: =IF(COUNT(Q55:T55)=0,"",ROUND(AVERAGE(Q55:T55),0)) | V55: =IF(U55="","",LOOKUP(U55,Impostazioni!$E$4:$E$9,Impostazioni!$F$4:$F$9)) | AA55: =IF(COUNT(W55:Z55)=0,"",ROUND(AVERAGE(W55:Z55),0)) | AB55: =IF(AA55="","",LOOKUP(AA55,Impostazioni!$E$4:$E$9,Impostazioni!$F$4:$F$9))
A56: 10 | B56: =IFERROR(INDEX(Alunni!$C$1:$C$1000,MATCH($A56,Alunni!$A$1:$A$1000,0))&"","") | I56: =IF(COUNT(E56:H56)=0,"",ROUND(AVERAGE(E56:H56),0)) | J56: =IF(I56="","",LOOKUP(I56,Impostazioni!$E$4:$E$9,Impostazioni!$F$4:$F$9)) | O56: =IF(COUNT(K56:N56)=0,"",ROUND(AVERAGE(K56:N56),0)) | P56: =IF(O56="","",LOOKUP(O56,Impostazioni!$E$4:$E$9,Impostazioni!$F$4:$F$9)) | U56: =IF(COUNT(Q56:T56)=0,"",ROUND(AVERAGE(Q56:T56),0)) | V56: =IF(U56="","",LOOKUP(U56,Impostazioni!$E$4:$E$9,Impostazioni!$F$4:$F$9)) | AA56: =IF(COUNT(W56:Z56)=0,"",ROUND(AVERAGE(W56:Z56),0)) | AB56: =IF(AA56="","",LOOKUP(AA56,Impostazioni!$E$4:$E$9,Impostazioni!$F$4:$F$9))
A57: 11 | B57: =IFERROR(INDEX(Alunni!$C$1:$C$1000,MATCH($A57,Alunni!$A$1:$A$1000,0))&"","") | I57: =IF(COUNT(E57:H57)=0,"",ROUND(AVERAGE(E57:H57),0)) | J57: =IF(I57="","",LOOKUP(I57,Impostazioni!$E$4:$E$9,Impostazioni!$F$4:$F$9)) | O57: =IF(COUNT(K57:N57)=0,"",ROUND(AVERAGE(K57:N57),0)) | P57: =IF(O57="","",LOOKUP(O57,Impostazioni!$E$4:$E$9,Impostazioni!$F$4:$F$9)) | U57: =IF(COUNT(Q57:T57)=0,"",ROUND(AVERAGE(Q57:T57),0)) | V57: =IF(U57="","",LOOKUP(U57,Impostazioni!$E$4:$E$9,Impostazioni!$F$4:$F$9)) | AA57: =IF(COUNT(W57:Z57)=0,"",ROUND(AVERAGE(W57:Z57),0)) | AB57: =IF(AA57="","",LOOKUP(AA57,Impostazioni!$E$4:$E$9,Impostazioni!$F$4:$F$9))
...

Sheet Riepilogo
A1: RIEPILOGO E GIUDIZI · MODELLO-5 · classe 5ª · 1° e 2° quadrimestre
A2: Gialle = tue. Il giudizio definitivo prevale. Verde = da riportare. «+» in alto mostra le medie di dettaglio.
E4: 1° QUADRIMESTRE | AJ4: 2° QUADRIMESTRE
E5: MEDIE PER SOTTO-OBIETTIVO | M5: ="OB. A · "&Impostazioni!B17 -> OB. A · Organizzare movimenti finalizzati valutando traiettorie, distanze e ritmi anche in situazioni nuove, con piena autonomia. | R5: ="OB. B · "&Impostazioni!B18 -> OB. B · Applicare correttamente le modalità di gioco-sport e svolgere un ruolo attivo nel gruppo, rispettando regole e avversari. | W5: TECNOLOGIA | Z5: ED. CIVICA | AC5: PROCESSO E AVVISI | AF5: DA RIPORTARE NEL DOCUMENTO | AJ5: MEDIE PER SOTTO-OBIETTIVO | AR5: ="OB. A · "&Impostazioni!B19 -> OB. A · Elaborare ed eseguire sequenze e coreografie individuali e collettive in modo personale e coordinato. | AW5: ="OB. B · "&Impostazioni!B20 -> OB. B · Collegare alimentazione, esercizio e benessere verso stili di vita attivi, muovendosi in sicurezza anche in contesti nuovi e all'aperto. | BB5: TECNOLOGIA | BE5: ED. CIVICA | BH5: PROCESSO E AVVISI | BK5: DA RIPORTARE NEL DOCUMENTO
A7: N° | B7: Alunno | C7: Stato | D7: OP | E7: 1.1 Traiettorie, ritmi, organizzazione | F7: 2.1 Sequenze e coreografie | G7: 3.1 Modalità esecutive gioco-sport | H7: 3.2 Partecipare e collaborare | I7: 3.3 Regole, sconfitta e vittoria | J7: 4.1 Muoversi negli ambienti | K7: 4.2 Alimentazione ed esercizio | L7: 4.3 Prevenzione e sicurezza | M7: n. voti | N7: Media voti | O7: Valore finale | P7: Giudizio calcolato | Q7: Giudizio definitivo | R7: n. voti | S7: Media voti | T7: Valore finale | U7: Giudizio calcolato | V7: Giudizio definitivo | W7: Media | X7: Giudizio calcolato | Y7: Giudizio definitivo | Z7: Media | AA7: Giudizio calcolato | AB7: Giudizio definitivo | AC7: Rubrica di processo (10–5) | AD7: Prove da recuperare | AE7: Avvisi | AF7: Ob. A | AG7: Ob. B | AH7: Tecnologia | AI7: Ed. civica | AJ7: 1.1 Traiettorie, ritmi, organizzazione | AK7: 2.1 Sequenze e coreografie | AL7: 3.1 Modalità esecutive gioco-sport | AM7: 3.2 Partecipare e collaborare | AN7: 3.3 Regole, sconfitta e vittoria | AO7: 4.1 Muoversi negli ambienti | AP7: 4.2 Alimentazione ed esercizio | AQ7: 4.3 Prevenzione e sicurezza | AR7: n. voti | AS7: Media voti | AT7: Valore finale | AU7: Giudizio calcolato | AV7: Giudizio definitivo | AW7: n. voti | AX7: Media voti | AY7: Valore finale | AZ7: Giudizio calcolato | BA7: Giudizio definitivo | BB7: Media | BC7: Giudizio calcolato | BD7: Giudizio definitivo | BE7: Media | BF7: Giudizio calcolato | BG7: Giudizio definitivo | BH7: Rubrica di processo (10–5) | BI7: Prove da recuperare | BJ7: Avvisi | BK7: Ob. A | BL7: Ob. B | BM7: Tecnologia | BN7: Ed. civica | BO7: Commento del docente
A8: 1 | B8: =IFERROR(INDEX(Alunni!$C$1:$C$1000,MATCH($A8,Alunni!$A$1:$A$1000,0))&"","") -> Rossi Mario (esempio) | C8: =IFERROR(INDEX(Alunni!$D$1:$D$1000,MATCH($A8,Alunni!$A$1:$A$1000,0))&"","") -> Attivo | D8: =IFERROR(INDEX(Alunni!$E$1:$E$1000,MATCH($A8,Alunni!$A$1:$A$1000,0))&"","") | E8: =IF($B8="","",IFERROR(ROUND(SUMPRODUCT((Dati!$C$3:$AP$3="1.1")*INDEX(Dati!$C$1:$AP$1000,MATCH($A8,Dati!$A$1:$A$1000,0),0)*INDEX(Dati!$CE$1:$DR$1000,MATCH($A8,Dati!$A$1:$A$1000,0),0))/SUMPRODUCT((Dati!$C$3:$AP$3="1.1")*INDEX(Dati!$CE$1:$DR$1000,MATCH($A8,Dati!$A$1:$A$1000,0),0)),2),"")) -> 8 | F8: =IF($B8="","",IFERROR(ROUND(SUMPRODUCT((Dati!$C$3:$AP$3="2.1")*INDEX(Dati!$C$1:$AP$1000,MATCH($A8,Dati!$A$1:$A$1000,0),0)*INDEX(Dati!$CE$1:$DR$1000,MATCH($A8,Dati!$A$1:$A$1000,0),0))/SUMPRODUCT((Dati!$C$3:$AP$3="2.1")*INDEX(Dati!$CE$1:$DR$1000,MATCH($A8,Dati!$A$1:$A$1000,0),0)),2),"")) | G8: =IF($B8="","",IFERROR(ROUND(SUMPRODUCT((Dati!$C$3:$AP$3="3.1")*INDEX(Dati!$C$1:$AP$1000,MATCH($A8,Dati!$A$1:$A$1000,0),0)*INDEX(Dati!$CE$1:$DR$1000,MATCH($A8,Dati!$A$1:$A$1000,0),0))/SUMPRODUCT((Dati!$C$3:$AP$3="3.1")*INDEX(Dati!$CE$1:$DR$1000,MATCH($A8,Dati!$A$1:$A$1000,0),0)),2),"")) -> 8 | H8: =IF($B8="","",IFERROR(ROUND(SUMPRODUCT((Dati!$C$3:$AP$3="3.2")*INDEX(Dati!$C$1:$AP$1000,MATCH($A8,Dati!$A$1:$A$1000,0),0)*INDEX(Dati!$CE$1:$DR$1000,MATCH($A8,Dati!$A$1:$A$1000,0),0))/SUMPRODUCT((Dati!$C$3:$AP$3="3.2")*INDEX(Dati!$CE$1:$DR$1000,MATCH($A8,Dati!$A$1:$A$1000,0),0)),2),"")) | I8: =IF($B8="","",IFERROR(ROUND(SUMPRODUCT((Dati!$C$3:$AP$3="3.3")*INDEX(Dati!$C$1:$AP$1000,MATCH($A8,Dati!$A$1:$A$1000,0),0)*INDEX(Dati!$CE$1:$DR$1000,MATCH($A8,Dati!$A$1:$A$1000,0),0))/SUMPRODUCT((Dati!$C$3:$AP$3="3.3")*INDEX(Dati!$CE$1:$DR$1000,MATCH($A8,Dati!$A$1:$A$1000,0),0)),2),"")) -> 8 | J8: =IF($B8="","",IFERROR(ROUND(SUMPRODUCT((Dati!$C$3:$AP$3="4.1")*INDEX(Dati!$C$1:$AP$1000,MATCH($A8,Dati!$A$1:$A$1000,0),0)*INDEX(Dati!$CE$1:$DR$1000,MATCH($A8,Dati!$A$1:$A$1000,0),0))/SUMPRODUCT((Dati!$C$3:$AP$3="4.1")*INDEX(Dati!$CE$1:$DR$1000,MATCH($A8,Dati!$A$1:$A$1000,0),0)),2),"")) | K8: =IF($B8="","",IFERROR(ROUND(SUMPRODUCT((Dati!$C$3:$AP$3="4.2")*INDEX(Dati!$C$1:$AP$1000,MATCH($A8,Dati!$A$1:$A$1000,0),0)*INDEX(Dati!$CE$1:$DR$1000,MATCH($A8,Dati!$A$1:$A$1000,0),0))/SUMPRODUCT((Dati!$C$3:$AP$3="4.2")*INDEX(Dati!$CE$1:$DR$1000,MATCH($A8,Dati!$A$1:$A$1000,0),0)),2),"")) | L8: =IF($B8="","",IFERROR(ROUND(SUMPRODUCT((Dati!$C$3:$AP$3="4.3")*INDEX(Dati!$C$1:$AP$1000,MATCH($A8,Dati!$A$1:$A$1000,0),0)*INDEX(Dati!$CE$1:$DR$1000,MATCH($A8,Dati!$A$1:$A$1000,0),0))/SUMPRODUCT((Dati!$C$3:$AP$3="4.3")*INDEX(Dati!$CE$1:$DR$1000,MATCH($A8,Dati!$A$1:$A$1000,0),0)),2),"")) | M8: =IF($B8="","",IFERROR(SUMPRODUCT((Dati!$C$4:$AP$4="A")*(INDEX(Dati!$CE$1:$DR$1000,MATCH($A8,Dati!$A$1:$A$1000,0),0)>0)),0)) -> 2 | N8: =IF($B8="","",IFERROR(ROUND(SUMPRODUCT((Dati!$C$4:$AP$4="A")*INDEX(Dati!$C$1:$AP$1000,MATCH($A8,Dati!$A$1:$A$1000,0),0)*INDEX(Dati!$CE$1:$DR$1000,MATCH($A8,Dati!$A$1:$A$1000,0),0))/SUMPRODUCT((Dati!$C$4:$AP$4="A")*INDEX(Dati!$CE$1:$DR$1000,MATCH($A8,Dati!$A$1:$A$1000,0),0)),2),"")) -> 8 | O8: =IF(N8="","",IF(ISNUMBER(AC8),ROUND(Impostazioni!$B$12*N8+Impostazioni!$B$13*AC8,2),N8)) -> 8 | P8: =IF(O8="","",LOOKUP(O8,Impostazioni!$E$4:$E$9,Impostazioni!$F$4:$F$9)) -> Buono | R8: =IF($B8="","",IFERROR(SUMPRODUCT((Dati!$C$4:$AP$4="B")*(INDEX(Dati!$CE$1:$DR$1000,MATCH($A8,Dati!$A$1:$A$1000,0),0)>0)),0)) -> 2 | S8: =IF($B8="","",IFERROR(ROUND(SUMPRODUCT((Dati!$C$4:$AP$4="B")*INDEX(Dati!$C$1:$AP$1000,MATCH($A8,Dati!$A$1:$A$1000,0),0)*INDEX(Dati!$CE$1:$DR$1000,MATCH($A8,Dati!$A$1:$A$1000,0),0))/SUMPRODUCT((Dati!$C$4:$AP$4="B")*INDEX(Dati!$CE$1:$DR$1000,MATCH($A8,Dati!$A$1:$A$1000,0),0)),2),"")) -> 8 | T8: =IF(S8="","",IF(ISNUMBER(AC8),ROUND(Impostazioni!$B$12*S8+Impostazioni!$B$13*AC8,2),S8)) -> 8 | U8: =IF(T8="","",LOOKUP(T8,Impostazioni!$E$4:$E$9,Impostazioni!$F$4:$F$9)) -> Buono | W8: =IF($B8="","",IFERROR(ROUND(SUMPRODUCT((Dati!$C$4:$AP$4="TEC")*INDEX(Dati!$C$1:$AP$1000,MATCH($A8,Dati!$A$1:$A$1000,0),0)*INDEX(Dati!$CE$1:$DR$1000,MATCH($A8,Dati!$A$1:$A$1000,0),0))/SUMPRODUCT((Dati!$C$4:$AP$4="TEC")*INDEX(Dati!$CE$1:$DR$1000,MATCH($A8,Dati!$A$1:$A$1000,0),0)),2),"")) -> 7 | X8: =IF(W8="","",LOOKUP(W8,Impostazioni!$E$4:$E$9,Impostazioni!$F$4:$F$9)) -> Discreto | Z8: =IF($B8="","",IFERROR(ROUND(SUMPRODUCT((Dati!$C$4:$AP$4="CIV")*INDEX(Dati!$C$1:$AP$1000,MATCH($A8,Dati!$A$1:$A$1000,0),0)*INDEX(Dati!$CE$1:$DR$1000,MATCH($A8,Dati!$A$1:$A$1000,0),0))/SUMPRODUCT((Dati!$C$4:$AP$4="CIV")*INDEX(Dati!$CE$1:$DR$1000,MATCH($A8,Dati!$A$1:$A$1000,0),0)),2),"")) | AA8: =IF(Z8="","",LOOKUP(Z8,Impostazioni!$E$4:$E$9,Impostazioni!$F$4:$F$9)) | AD8: =IF($B8="","",IFERROR(SUM(INDEX(Dati!$FG$1:$FP$1000,MATCH($A8,Dati!$A$1:$A$1000,0),0)),0)) -> 0 | AE8: =IF($B8="","",IF($C8="ES","Esonerato: concordare con referente e dirigente",IF($C8="Ritirato","Ritirato",TRIM(IF(OR(N(M8)<Impostazioni!$B$14,N(R8)<Impostazioni!$B$14),"Pochi voti: valutazione alternativa (scritta/orale). ","")&IF(N(AD8)>0,"Da recuperare: "&AD8&". ","")&IF($D8="OP","Riferito agli obiettivi personalizzati.",""))))) | AF8: =IF($B8="","",IF($C8="ES","ES",IF(Q8<>"",Q8,P8))) -> Buono | AG8: =IF($B8="","",IF($C8="ES","ES",IF(V8<>"",V8,U8))) -> Buono | AH8: =IF($B8="","",IF($C8="ES","ES",IF(Y8<>"",Y8,X8))) -> Discreto | AI8: =IF($B8="","",IF($C8="ES","ES",IF(AB8<>"",AB8,AA8))) | AJ8: =IF($B8="","",IFERROR(ROUND(SUMPRODUCT((Dati!$AQ$3:$CD$3="1.1")*INDEX(Dati!$AQ$1:$CD$1000,MATCH($A8,Dati!$A$1:$A$1000,0),0)*INDEX(Dati!$DS$1:$FF$1000,MATCH($A8,Dati!$A$1:$A$1000,0),0))/SUMPRODUCT((Dati!$AQ$3:$CD$3="1.1")*INDEX(Dati!$DS$1:$FF$1000,MATCH($A8,Dati!$A$1:$A$1000,0),0)),2),"")) | AK8: =IF($B8="","",IFERROR(ROUND(SUMPRODUCT((Dati!$AQ$3:$CD$3="2.1")*INDEX(Dati!$AQ$1:$CD$1000,MATCH($A8,Dati!$A$1:$A$1000,0),0)*INDEX(Dati!$DS$1:$FF$1000,MATCH($A8,Dati!$A$1:$A$1000,0),0))/SUMPRODUCT((Dati!$AQ$3:$CD$3="2.1")*INDEX(Dati!$DS$1:$FF$1000,MATCH($A8,Dati!$A$1:$A$1000,0),0)),2),"")) | AL8: =IF($B8="","",IFERROR(ROUND(SUMPRODUCT((Dati!$AQ$3:$CD$3="3.1")*INDEX(Dati!$AQ$1:$CD$1000,MATCH($A8,Dati!$A$1:$A$1000,0),0)*INDEX(Dati!$DS$1:$FF$1000,MATCH($A8,Dati!$A$1:$A$1000,0),0))/SUMPRODUCT((Dati!$AQ$3:$CD$3="3.1")*INDEX(Dati!$DS$1:$FF$1000,MATCH($A8,Dati!$A$1:$A$1000,0),0)),2),"")) | AM8: =IF($B8="","",IFERROR(ROUND(SUMPRODUCT((Dati!$AQ$3:$CD$3="3.2")*INDEX(Dati!$AQ$1:$CD$1000,MATCH($A8,Dati!$A$1:$A$1000,0),0)*INDEX(Dati!$DS$1:$FF$1000,MATCH($A8,Dati!$A$1:$A$1000,0),0))/SUMPRODUCT((Dati!$AQ$3:$CD$3="3.2")*INDEX(Dati!$DS$1:$FF$1000,MATCH($A8,Dati!$A$1:$A$1000,0),0)),2),"")) | AN8: =IF($B8="","",IFERROR(ROUND(SUMPRODUCT((Dati!$AQ$3:$CD$3="3.3")*INDEX(Dati!$AQ$1:$CD$1000,MATCH($A8,Dati!$A$1:$A$1000,0),0)*INDEX(Dati!$DS$1:$FF$1000,MATCH($A8,Dati!$A$1:$A$1000,0),0))/SUMPRODUCT((Dati!$AQ$3:$CD$3="3.3")*INDEX(Dati!$DS$1:$FF$1000,MATCH($A8,Dati!$A$1:$A$1000,0),0)),2),"")) | AO8: =IF($B8="","",IFERROR(ROUND(SUMPRODUCT((Dati!$AQ$3:$CD$3="4.1")*INDEX(Dati!$AQ$1:$CD$1000,MATCH($A8,Dati!$A$1:$A$1000,0),0)*INDEX(Dati!$DS$1:$FF$1000,MATCH($A8,Dati!$A$1:$A$1000,0),0))/SUMPRODUCT((Dati!$AQ$3:$CD$3="4.1")*INDEX(Dati!$DS$1:$FF$1000,MATCH($A8,Dati!$A$1:$A$1000,0),0)),2),"")) | AP8: =IF($B8="","",IFERROR(ROUND(SUMPRODUCT((Dati!$AQ$3:$CD$3="4.2")*INDEX(Dati!$AQ$1:$CD$1000,MATCH($A8,Dati!$A$1:$A$1000,0),0)*INDEX(Dati!$DS$1:$FF$1000,MATCH($A8,Dati!$A$1:$A$1000,0),0))/SUMPRODUCT((Dati!$AQ$3:$CD$3="4.2")*INDEX(Dati!$DS$1:$FF$1000,MATCH($A8,Dati!$A$1:$A$1000,0),0)),2),"")) | AQ8: =IF($B8="","",IFERROR(ROUND(SUMPRODUCT((Dati!$AQ$3:$CD$3="4.3")*INDEX(Dati!$AQ$1:$CD$1000,MATCH($A8,Dati!$A$1:$A$1000,0),0)*INDEX(Dati!$DS$1:$FF$1000,MATCH($A8,Dati!$A$1:$A$1000,0),0))/SUMPRODUCT((Dati!$AQ$3:$CD$3="4.3")*INDEX(Dati!$DS$1:$FF$1000,MATCH($A8,Dati!$A$1:$A$1000,0),0)),2),"")) | AR8: =IF($B8="","",IFERROR(SUMPRODUCT((Dati!$AQ$4:$CD$4="A")*(INDEX(Dati!$DS$1:$FF$1000,MATCH($A8,Dati!$A$1:$A$1000,0),0)>0)),0)) -> 0 | AS8: =IF($B8="","",IFERROR(ROUND(SUMPRODUCT((Dati!$AQ$4:$CD$4="A")*INDEX(Dati!$AQ$1:$CD$1000,MATCH($A8,Dati!$A$1:$A$1000,0),0)*INDEX(Dati!$DS$1:$FF$1000,MATCH($A8,Dati!$A$1:$A$1000,0),0))/SUMPRODUCT((Dati!$AQ$4:$CD$4="A")*INDEX(Dati!$DS$1:$FF$1000,MATCH($A8,Dati!$A$1:$A$1000,0),0)),2),"")) | AT8: =IF(AS8="","",IF(ISNUMBER(BH8),ROUND(Impostazioni!$B$12*AS8+Impostazioni!$B$13*BH8,2),AS8)) | AU8: =IF(AT8="","",LOOKUP(AT8,Impostazioni!$E$4:$E$9,Impostazioni!$F$4:$F$9)) | AW8: =IF($B8="","",IFERROR(SUMPRODUCT((Dati!$AQ$4:$CD$4="B")*(INDEX(Dati!$DS$1:$FF$1000,MATCH($A8,Dati!$A$1:$A$1000,0),0)>0)),0)) -> 0 | AX8: =IF($B8="","",IFERROR(ROUND(SUMPRODUCT((Dati!$AQ$4:$CD$4="B")*INDEX(Dati!$AQ$1:$CD$1000,MATCH($A8,Dati!$A$1:$A$1000,0),0)*INDEX(Dati!$DS$1:$FF$1000,MATCH($A8,Dati!$A$1:$A$1000,0),0))/SUMPRODUCT((Dati!$AQ$4:$CD$4="B")*INDEX(Dati!$DS$1:$FF$1000,MATCH($A8,Dati!$A$1:$A$1000,0),0)),2),"")) | AY8: =IF(AX8="","",IF(ISNUMBER(BH8),ROUND(Impostazioni!$B$12*AX8+Impostazioni!$B$13*BH8,2),AX8)) | AZ8: =IF(AY8="","",LOOKUP(AY8,Impostazioni!$E$4:$E$9,Impostazioni!$F$4:$F$9)) | BB8: =IF($B8="","",IFERROR(ROUND(SUMPRODUCT((Dati!$AQ$4:$CD$4="TEC")*INDEX(Dati!$AQ$1:$CD$1000,MATCH($A8,Dati!$A$1:$A$1000,0),0)*INDEX(Dati!$DS$1:$FF$1000,MATCH($A8,Dati!$A$1:$A$1000,0),0))/SUMPRODUCT((Dati!$AQ$4:$CD$4="TEC")*INDEX(Dati!$DS$1:$FF$1000,MATCH($A8,Dati!$A$1:$A$1000,0),0)),2),"")) | BC8: =IF(BB8="","",LOOKUP(BB8,Impostazioni!$E$4:$E$9,Impostazioni!$F$4:$F$9)) | BE8: =IF($B8="","",IFERROR(ROUND(SUMPRODUCT((Dati!$AQ$4:$CD$4="CIV")*INDEX(Dati!$AQ$1:$CD$1000,MATCH($A8,Dati!$A$1:$A$1000,0),0)*INDEX(Dati!$DS$1:$FF$1000,MATCH($A8,Dati!$A$1:$A$1000,0),0))/SUMPRODUCT((Dati!$AQ$4:$CD$4="CIV")*INDEX(Dati!$DS$1:$FF$1000,MATCH($A8,Dati!$A$1:$A$1000,0),0)),2),"")) | BF8: =IF(BE8="","",LOOKUP(BE8,Impostazioni!$E$4:$E$9,Impostazioni!$F$4:$F$9)) | BI8: =IF($B8="","",IFERROR(SUM(INDEX(Dati!$FQ$1:$FZ$1000,MATCH($A8,Dati!$A$1:$A$1000,0),0)),0)) -> 0 | BJ8: =IF($B8="","",IF($C8="ES","Esonerato: concordare con referente e dirigente",IF($C8="Ritirato","Ritirato",TRIM(IF(OR(N(AR8)<Impostazioni!$B$14,N(AW8)<Impostazioni!$B$14),"Pochi voti: valutazione alternativa (scritta/orale). ","")&IF(N(BI8)>0,"Da recuperare: "&BI8&". ","")&IF($D8="OP","Riferito agli obiettivi personalizzati.",""))))) -> Pochi voti: valutazione alternativa (scritta/orale). | BK8: =IF($B8="","",IF($C8="ES","ES",IF(AV8<>"",AV8,AU8))) | BL8: =IF($B8="","",IF($C8="ES","ES",IF(BA8<>"",BA8,AZ8))) | BM8: =IF($B8="","",IF($C8="ES","ES",IF(BD8<>"",BD8,BC8))) | BN8: =IF($B8="","",IF($C8="ES","ES",IF(BG8<>"",BG8,BF8)))
